Workbook
Name solver_eng: 1
Name solver_neg: 1
Name solver_num: 0
Name solver_opt: Sheet1!$F$2
Name solver_typ: 1
Name solver_val: 0
Name solver_ver: 3

Sheet Sheet5

Sheet Sheet9
A1: opponent | B1: dad
A2: win/loss | B2: (All)
A4: Average of win/loss | B4: Column Labels
A5: Row Labels | B5: dad | C5: ted | D5: Grand Total
A6: 0 | B6: 0.4 | C6: 0.55 | D6: 0.46666667
A7: 1 | B7: 0.25 | C7: 0.375 | D7: 0.3125
A8: 2 | B8: 0 | C8: 0.16666667 | D8: 0.11111111
A9: 3 | B9: 0.25 | C9: 0.8 | D9: 0.55555556
A10: 4 | B10: 0.5 | C10: 0 | D10: 0.2
A11: 5 | B11: 0 | C11: 0 | D11: 0
A12: 6 | B12: 0.5 | D12: 0.5
A13: 7 | C13: 0 | D13: 0
A14: Grand Total | B14: 0.3125 | C14: 0.43181818 | D14: 0.36956522
A18: opponent | B18: dad
A20: Count of win/loss | B20: Column Labels
A21: Row Labels | B21: 0 | C21: 1 | D21: Grand Total
A22: 0 | B22: 0.4137931 | C22: 0.61764706 | D22: 0.48913043
A23: 1 | B23: 0.18965517 | C23: 0.14705882 | D23: 0.17391304
A24: 2 | B24: 0.13793103 | C24: 0.029411765 | D24: 0.097826087
A25: 3 | B25: 0.068965517 | C25: 0.14705882 | D25: 0.097826087
A26: 4 | B26: 0.068965517 | C26: 0.029411765 | D26: 0.054347826
A27: 5 | B27: 0.086206897 | C27: 0 | D27: 0.054347826
A28: 6 | B28: 0.017241379 | C28: 0.029411765 | D28: 0.02173913
A29: 7 | B29: 0.017241379 | C29: 0 | D29: 0.010869565
A30: Grand Total | B30: 1 | C30: 1 | D30: 1

Sheet Sheet2
A1: SUMMARY OUTPUT
A3: Regression Statistics
A4: Multiple R | B4: 0.14524793
A5: R Square | B5: 0.021096962
A6: Adjusted R Square | B6: 0.017001134
A7: Standard Error | B7: 0.49675892
A8: Observations | B8: 241
A10: ANOVA
B11: df | C11: SS | D11: MS | E11: F | F11: Significance F
A12: Regression | B12: 1 | C12: 1.2710701 | D12: 1.2710701 | E12: 5.1508411 | F12: 0.024126856
A13: Residual | B13: 239 | C13: 58.977893 | D13: 0.24676942
A14: Total | B14: 240 | C14: 60.248963
B16: Coefficients | C16: Standard Error | D16: t Stat | E16: P-value | F16: Lower 95% | G16: Upper 95% | H16: Lower 95.0% | I16: Upper 95.0%
A17: Intercept | B17: 0.42975207 | C17: 0.045159902 | D17: 9.5162312 | E17: 2.0594138e-18 | F17: 0.3407898 | G17: 0.51871434 | H17: 0.3407898 | I17: 0.51871434
A18: TedBreak(1=TRUE) | B18: 0.14524793 | C18: 0.063998661 | D18: 2.2695465 | E18: 0.024126856 | F18: 0.01917445 | G18: 0.27132142 | H18: 0.01917445 | I18: 0.27132142
A22: RESIDUAL OUTPUT
A24: Observation | B24: Predicted win/loss | C24: Residuals
A25: 1 | B25: 0.42975207 | C25: -0.42975207
A26: 2 | B26: 0.575 | C26: -0.575
A27: 3 | B27: 0.42975207 | C27: 0.57024793
A28: 4 | B28: 0.42975207 | C28: 0.57024793
A29: 5 | B29: 0.575 | C29: 0.425
A30: 6 | B30: 0.42975207 | C30: -0.42975207
A31: 7 | B31: 0.42975207 | C31: -0.42975207
A32: 8 | B32: 0.42975207 | C32: -0.42975207
A33: 9 | B33: 0.575 | C33: 0.425
A34: 10 | B34: 0.42975207 | C34: 0.57024793
A35: 11 | B35: 0.42975207 | C35: -0.42975207
A36: 12 | B36: 0.575 | C36: -0.575
... A265: 241 | B265: 0.575 | C265: 0.425

Sheet Sheet1
A1: date | B1: GameCount | C1: location | D1: opponent | E1: win/loss | F1: win type | G1: loser remainder | H1: break | I1: winner remaining | L1: 9-game rolling WR | M1: Win rate | N1: Cumulative Wins | O1: TedBreak(1=TRUE)
A2: 42835 | B2: 1 | C2: station 280 | D2: dad | E2: 0 | F2: wrong pocket | G2: 0 | H2: dad | I2: 3 | M2: =N2/Sheet1!$B2 -> 0 | N2: =E2 -> 0 | O2: =IF(Sheet1!$H2="ted",1,0) -> 0 | P2: =SUMIF(O2:O200,1,Sheet1!$E$2:$E$613) -> 54 | Q2: =SUMIF(O2:O200,0,Sheet1!$E$2:$E$613) -> 42
A3: 42835 | B3: 2 | C3: station 280 | D3: dad | E3: 0 | F3: regulation | G3: 4 | H3: ted | I3: 0 | M3: =N3/Sheet1!$B3 -> 0 | N3: =E3+N2 -> 0 | O3: =IF(Sheet1!$H3="ted",1,0) -> 1
A4: 42835 | B4: 3 | C4: station 280 | D4: dad | E4: 1 | F4: early 8 | G4: 3 | H4: dad | I4: 4 | J4: Jered teammate | M4: =N4/Sheet1!$B4 -> 0.33333333 | N4: =E4+N3 -> 1 | O4: =IF(Sheet1!$H4="ted",1,0) -> 0
A5: 42839 | B5: 4 | C5: adams | D5: adam, josh | E5: 1 | F5: wrong pocket | G5: 0 | H5: josh | I5: 3 | M5: =N5/Sheet1!$B5 -> 0.5 | N5: =E5+N4 -> 2 | O5: =IF(Sheet1!$H5="ted",1,0) -> 0
A6: 42839 | B6: 5 | C6: adams | D6: adam josh | E6: 1 | F6: regulation | G6: 2 | H6: ted | I6: 0 | M6: =N6/Sheet1!$B6 -> 0.6 | N6: =E6+N5 -> 3 | O6: =IF(Sheet1!$H6="ted",1,0) -> 1
A7: 42839 | B7: 6 | C7: adams | D7: adam josh | E7: 0 | F7: early 8 | G7: 7 | H7: adam | I7: 7 | M7: =N7/Sheet1!$B7 -> 0.5 | N7: =E7+N6 -> 3 | O7: =IF(Sheet1!$H7="ted",1,0) -> 0
A8: 42839 | B8: 7 | C8: adams | D8: adam josh | E8: 0 | F8: regulation | G8: 1 | H8: jered | I8: 0 | M8: =N8/Sheet1!$B8 -> 0.42857143 | N8: =E8+N7 -> 3 | O8: =IF(Sheet1!$H8="ted",1,0) -> 0
A9: 42839 | B9: 8 | C9: adams | D9: josh Jered | E9: 0 | F9: regulation | G9: 1 | H9: josh | I9: 0 | J9: adam team | M9: =N9/Sheet1!$B9 -> 0.375 | N9: =E9+N8 -> 3 | O9: =IF(Sheet1!$H9="ted",1,0) -> 0
A10: 42839 | B10: 9 | C10: adams | D10: josh Jered | E10: 1 | F10: regulation | G10: 1 | H10: ted | I10: 0 | K10: 0.5 | L10: =SUM(E2:E10)/9 -> 0.44444444 | M10: =N10/Sheet1!$B10 -> 0.44444444 | N10: =E10+N9 -> 4 | O10: =IF(Sheet1!$H10="ted",1,0) -> 1
A11: 42839 | B11: 10 | C11: adams | D11: josh Jered | E11: 1 | F11: regulation | G11: 1 | H11: jered | I11: 0 | K11: 0.5 | L11: =SUM(E3:E11)/9 -> 0.55555556 | M11: =N11/Sheet1!$B11 -> 0.5 | N11: =E11+N10 -> 5 | O11: =IF(Sheet1!$H11="ted",1,0) -> 0
A12: 42846 | B12: 11 | C12: station 280 | D12: dad | E12: 0 | F12: regulation | G12: 0 | H12: dad | I12: 0 | K12: 0.5 | L12: =SUM(E4:E12)/9 -> 0.55555556 | M12: =N12/Sheet1!$B12 -> 0.45454545 | N12: =E12+N11 -> 5 | O12: =IF(Sheet1!$H12="ted",1,0) -> 0
A13: 42846 | B13: 12 | C13: station 280 | D13: dad | E13: 0 | F13: regulation | G13: 5 | H13: ted | I13: 0 | K13: 0.5 | L13: =SUM(E5:E13)/9 -> 0.44444444 | M13: =N13/Sheet1!$B13 -> 0.41666667 | N13: =E13+N12 -> 5 | O13: =IF(Sheet1!$H13="ted",1,0) -> 1
A14: 42846 | B14: 13 | C14: station 280 | D14: dad | E14: 0 | F14: regulation | G14: 3 | H14: dad | I14: 0 | K14: 0.5 | L14: =SUM(E6:E14)/9 -> 0.33333333 | M14: =N14/Sheet1!$B14 -> 0.38461538 | N14: =E14+N13 -> 5 | O14: =IF(Sheet1!$H14="ted",1,0) -> 0
A15: 42851 | B15: 14 | C15: station 280 | D15: dad | E15: 0 | F15: regulation | G15: 1 | H15: ted | I15: 0 | K15: 0.5 | L15: =SUM(E7:E15)/9 -> 0.22222222 | M15: =N15/Sheet1!$B15 -> 0.35714286 | N15: =E15+N14 -> 5 | O15: =IF(Sheet1!$H15="ted",1,0) -> 1
A16: 42854 | B16: 15 | C16: station 280 | D16: dad, josh | E16: 0 | F16: cutthroat | G16: dad | H16: dad | I16: josh | K16: 0.5 | L16: =SUM(E8:E16)/9 -> 0.22222222 | M16: =N16/Sheet1!$B16 -> 0.33333333 | N16: =E16+N15 -> 5 | O16: =IF(Sheet1!$H16="ted",1,0) -> 0
A17: 42854 | B17: 16 | C17: station 280 | D17: dad, josh | E17: 0 | F17: cutthroat | G17: dad | H17: ted | I17: josh | K17: 0.5 | L17: =SUM(E9:E17)/9 -> 0.22222222 | M17: =N17/Sheet1!$B17 -> 0.3125 | N17: =E17+N16 -> 5 | O17: =IF(Sheet1!$H17="ted",1,0) -> 1
A18: 42854 | B18: 17 | C18: station 280 | D18: dad, josh | E18: 0 | F18: cutthroat | G18: dad | H18: josh | I18: josh | K18: 0.5 | L18: =SUM(E10:E18)/9 -> 0.22222222 | M18: =N18/Sheet1!$B18 -> 0.29411765 | N18: =E18+N17 -> 5 | O18: =IF(Sheet1!$H18="ted",1,0) -> 0
A19: 42854 | B19: 18 | C19: station 280 | D19: dad, josh | E19: 0 | F19: cutthroat | G19: dad | H19: josh | I19: josh | K19: 0.5 | L19: =SUM(E11:E19)/9 -> 0.11111111 | M19: =N19/Sheet1!$B19 -> 0.27777778 | N19: =E19+N18 -> 5 | O19: =IF(Sheet1!$H19="ted",1,0) -> 0
A20: 42855 | B20: 19 | C20: dad's house | D20: josh | E20: 0 | F20: regulation | G20: 3 | H20: ted | I20: 0 | K20: 0.5 | L20: =SUM(E12:E20)/9 -> 0 | M20: =N20/Sheet1!$B20 -> 0.26315789 | N20: =E20+N19 -> 5 | O20: =IF(Sheet1!$H20="ted",1,0) -> 1
A21: 42855 | B21: 20 | C21: dad's house | D21: josh | E21: 1 | F21: regulation | G21: 0 | H21: josh | I21: 0 | K21: 0.5 | L21: =SUM(E13:E21)/9 -> 0.11111111 | M21: =N21/Sheet1!$B21 -> 0.3 | N21: =E21+N20 -> 6 | O21: =IF(Sheet1!$H21="ted",1,0) -> 0
A22: 42855 | B22: 21 | C22: dad's house | D22: josh | E22: 0 | F22: regulation | G22: 0 | H22: ted | I22: 0 | K22: 0.5 | L22: =SUM(E14:E22)/9 -> 0.11111111 | M22: =N22/Sheet1!$B22 -> 0.28571429 | N22: =E22+N21 -> 6 | O22: =IF(Sheet1!$H22="ted",1,0) -> 1
A23: 42855 | B23: 22 | C23: dad's house | D23: dad, josh | E23: 0 | F23: cutthroat | G23: ted | H23: josh | I23: josh | K23: 0.5 | L23: =SUM(E15:E23)/9 -> 0.11111111 | M23: =N23/Sheet1!$B23 -> 0.27272727 | N23: =E23+N22 -> 6 | O23: =IF(Sheet1!$H23="ted",1,0) -> 0
A24: 42855 | B24: 23 | C24: dad's house | D24: dad, josh | E24: 1 | F24: cutthroat | G24: dad | H24: josh | I24: ted | K24: 0.5 | L24: =SUM(E16:E24)/9 -> 0.22222222 | M24: =N24/Sheet1!$B24 -> 0.30434783 | N24: =E24+N23 -> 7 | O24: =IF(Sheet1!$H24="ted",1,0) -> 0
A25: 42855 | B25: 24 | C25: dad's house | D25: dad, josh | E25: 1 | F25: cutthroat | G25: dad | H25: ted | I25: ted | K25: 0.5 | L25: =SUM(E17:E25)/9 -> 0.33333333 | M25: =N25/Sheet1!$B25 -> 0.33333333 | N25: =E25+N24 -> 8 | O25: =IF(Sheet1!$H25="ted",1,0) -> 1
A26: 42866 | B26: 25 | C26: station 280 | D26: dad | E26: 0 | F26: regulation | G26: 2 | H26: dad | I26: 0 | K26: 0.5 | L26: =SUM(E18:E26)/9 -> 0.33333333 | M26: =N26/Sheet1!$B26 -> 0.32 | N26: =E26+N25 -> 8 | O26: =IF(Sheet1!$H26="ted",1,0) -> 0
A27: 42866 | B27: 26 | C27: station 280 | D27: dad | E27: 0 | F27: early 8 | G27: 2 | H27: ted | I27: 3 | K27: 0.5 | L27: =SUM(E19:E27)/9 -> 0.33333333 | M27: =N27/Sheet1!$B27 -> 0.30769231 | N27: =E27+N26 -> 8 | O27: =IF(Sheet1!$H27="ted",1,0) -> 1
A28: 42866 | B28: 27 | C28: station 280 | D28: dad | E28: 0 | F28: early 8 | G28: 5 | H28: dad | I28: 5 | K28: 0.5 | L28: =SUM(E20:E28)/9 -> 0.33333333 | M28: =N28/Sheet1!$B28 -> 0.2962963 | N28: =E28+N27 -> 8 | O28: =IF(Sheet1!$H28="ted",1,0) -> 0
A29: 42873 | B29: 28 | C29: sportys | D29: dad | E29: 1 | F29: regulation | G29: 1 | H29: dad | I29: 0 | K29: 0.5 | L29: =SUM(E21:E29)/9 -> 0.44444444 | M29: =N29/Sheet1!$B29 -> 0.32142857 | N29: =E29+N28 -> 9 | O29: =IF(Sheet1!$H29="ted",1,0) -> 0
A30: 42873 | B30: 29 | C30: sportys | D30: dad | E30: 1 | F30: early 8 | G30: 3 | H30: ted | I30: 3 | K30: 0.5 | L30: =SUM(E22:E30)/9 -> 0.44444444 | M30: =N30/Sheet1!$B30 -> 0.34482759 | N30: =E30+N29 -> 10 | O30: =IF(Sheet1!$H30="ted",1,0) -> 1
A31: 42873 | B31: 30 | C31: sportys | D31: riley | E31: 1 | F31: regulation | G31: 2 | H31: ted | I31: 0 | K31: 0.5 | L31: =SUM(E23:E31)/9 -> 0.55555556 | M31: =N31/Sheet1!$B31 -> 0.36666667 | N31: =E31+N30 -> 11 | O31: =IF(Sheet1!$H31="ted",1,0) -> 1
A32: 42890 | B32: 31 | C32: dad's house | D32: dad | E32: 1 | F32: regulation | G32: 0 | H32: ted | I32: 0 | K32: 0.5 | L32: =SUM(E24:E32)/9 -> 0.66666667 | M32: =N32/Sheet1!$B32 -> 0.38709677 | N32: =E32+N31 -> 12 | O32: =IF(Sheet1!$H32="ted",1,0) -> 1
A33: 42890 | B33: 32 | C33: dad's house | D33: dad | E33: 0 | F33: scratch on 8 | G33: 0 | H33: dad | I33: 0 | K33: 0.5 | L33: =SUM(E25:E33)/9 -> 0.55555556 | M33: =N33/Sheet1!$B33 -> 0.375 | N33: =E33+N32 -> 12 | O33: =IF(Sheet1!$H33="ted",1,0) -> 0
A34: 42890 | B34: 33 | C34: dad's house | D34: dad | E34: 1 | F34: scratch on 8 | G34: 0 | H34: ted | I34: 1 | K34: 0.5 | L34: =SUM(E26:E34)/9 -> 0.55555556 | M34: =N34/Sheet1!$B34 -> 0.39393939 | N34: =E34+N33 -> 13 | O34: =IF(Sheet1!$H34="ted",1,0) -> 1
A35: 42894 | B35: 34 | C35: station 280 | D35: dad | E35: 0 | F35: regulation | G35: 2 | H35: dad | I35: 0 | K35: 0.5 | L35: =SUM(E27:E35)/9 -> 0.55555556 | M35: =N35/Sheet1!$B35 -> 0.38235294 | N35: =E35+N34 -> 13 | O35: =IF(Sheet1!$H35="ted",1,0) -> 0
A36: 42894 | B36: 35 | C36: station 280 | D36: dad | E36: 1 | F36: early 8 | G36: 2 | H36: ted | I36: 4 | K36: 0.5 | L36: =SUM(E28:E36)/9 -> 0.66666667 | M36: =N36/Sheet1!$B36 -> 0.4 | N36: =E36+N35 -> 14 | O36: =IF(Sheet1!$H36="ted",1,0) -> 1
A37: 42894 | B37: 36 | C37: station 280 | D37: dad | E37: 1 | F37: regulation | G37: 0 | H37: dad | I37: 0 | K37: 0.5 | L37: =SUM(E29:E37)/9 -> 0.77777778 | M37: =N37/Sheet1!$B37 -> 0.41666667 | N37: =E37+N36 -> 15 | O37: =IF(Sheet1!$H37="ted",1,0) -> 0
... A74: 42964 | B74: 73 | C74: dad's house | D74: josh | E74: 1 | F74: regulation | G74: 4 | H74: ted | I74: 0 | K74: 0.5 | L74: =SUM(E66:E74)/9 -> 0.77777778 | M74: =N74/Sheet1!$B74 -> 0.39726027 | N74: =E74+N73 -> 29 | O74: =IF(Sheet1!$H74="ted",1,0) -> 1
A75: 42966 | B75: 74 | C75: station 280 | D75: Jered, dad | E75: 0 | F75: cutthroat | G75: dad | H75: ted | I75: jered | K75: 0.5 | L75: =SUM(E67:E75)/9 -> 0.77777778 | M75: =N75/Sheet1!$B75 -> 0.39189189 | N75: =E75+N74 -> 29 | O75: =IF(Sheet1!$H75="ted",1,0) -> 1
A76: 42966 | B76: 75 | C76: station 280 | D76: Jered, dad | E76: 1 | F76: cutthroat | G76: dad | H76: jered | I76: ted | K76: 0.5 | L76: =SUM(E68:E76)/9 -> 0.77777778 | M76: =N76/Sheet1!$B76 -> 0.4 | N76: =E76+N75 -> 30 | O76: =IF(Sheet1!$H76="ted",1,0) -> 0
...
